2024-08-11 19:57:03,138 INFO: Processing file: C:\projects\process mining\event logs\log1.csv
2024-08-11 19:57:03,157 ERROR: An error occurred while processing file: C:\projects\process mining\event logs\log1.csv 'case:concept:name'
Traceback (most recent call last):
  File "c:\projects\Process mining\test.py", line 58, in start_analyser
    log = log_converter.apply(df)
          ^^^^^^^^^^^^^^^^^^^^^^^
  File "C:\Users\it_su\AppData\Local\Packages\PythonSoftwareFoundation.Python.3.11_qbz5n2kfra8p0\LocalCache\local-packages\Python311\site-packages\pm4py\objects\conversion\log\converter.py", line 37, in apply
    return variant.value.apply(log, parameters=parameters)
           ^^^^^^^^^^^^^^^^^^^^^^^^^^^^^^^^^^^^^^^^^^^^^^^
  File "C:\Users\it_su\AppData\Local\Packages\PythonSoftwareFoundation.Python.3.11_qbz5n2kfra8p0\LocalCache\local-packages\Python311\site-packages\pm4py\objects\conversion\log\variants\to_event_log.py", line 52, in apply
    return __transform_event_stream_to_event_log(log, case_glue=glue, include_case_attributes=True,
           ^^^^^^^^^^^^^^^^^^^^^^^^^^^^^^^^^^^^^^^^^^^^^^^^^^^^^^^^^^^^^^^^^^^^^^^^^^^^^^^^^^^^^^^^
  File "C:\Users\it_su\AppData\Local\Packages\PythonSoftwareFoundation.Python.3.11_qbz5n2kfra8p0\LocalCache\local-packages\Python311\site-packages\pm4py\objects\conversion\log\variants\to_event_log.py", line 89, in __transform_event_stream_to_event_log
    glue = event[case_glue]
           ~~~~~^^^^^^^^^^^
  File "C:\Users\it_su\AppData\Local\Packages\PythonSoftwareFoundation.Python.3.11_qbz5n2kfra8p0\LocalCache\local-packages\Python311\site-packages\pm4py\objects\log\obj.py", line 60, in __getitem__
    return self._dict[key]
           ~~~~~~~~~~^^^^^
KeyError: 'case:concept:name'

2024-08-11 20:00:36,658 INFO: Processing file: C:\projects\process mining\event logs\log1.csv
2024-08-11 20:00:36,669 ERROR: An error occurred while processing file: C:\projects\process mining\event logs\log1.csv 'Marking' object has no attribute 'apply'
Traceback (most recent call last):
  File "c:\projects\Process mining\test.py", line 67, in start_analyser
    bpmn_graph = bpmn_factory.apply(net, initial_marking, final_marking)
                 ^^^^^^^^^^^^^^^^^^^^^^^^^^^^^^^^^^^^^^^^^^^^^^^^^^^^^^^
  File "C:\Users\it_su\AppData\Local\Packages\PythonSoftwareFoundation.Python.3.11_qbz5n2kfra8p0\LocalCache\local-packages\Python311\site-packages\pm4py\visualization\bpmn\visualizer.py", line 53, in apply
    return exec_utils.get_variant(variant).apply(bpmn_graph, parameters=parameters)
           ^^^^^^^^^^^^^^^^^^^^^^^^^^^^^^^^^^^^^
AttributeError: 'Marking' object has no attribute 'apply'

2024-08-11 20:03:14,153 INFO: Processing file: C:\projects\process mining\event logs\log1.csv
2024-08-11 20:03:14,163 ERROR: An error occurred while processing file: C:\projects\process mining\event logs\log1.csv 'Marking' object has no attribute 'apply'
Traceback (most recent call last):
  File "c:\projects\Process mining\test.py", line 70, in start_analyser
    bpmn_graph = bpmn_visualizer.apply(net, initial_marking, final_marking)
                 ^^^^^^^^^^^^^^^^^^^^^^^^^^^^^^^^^^^^^^^^^^^^^^^^^^^^^^^^^^
  File "C:\Users\it_su\AppData\Local\Packages\PythonSoftwareFoundation.Python.3.11_qbz5n2kfra8p0\LocalCache\local-packages\Python311\site-packages\pm4py\visualization\bpmn\visualizer.py", line 53, in apply
    return exec_utils.get_variant(variant).apply(bpmn_graph, parameters=parameters)
           ^^^^^^^^^^^^^^^^^^^^^^^^^^^^^^^^^^^^^
AttributeError: 'Marking' object has no attribute 'apply'

2024-08-11 20:03:35,828 INFO: Processing file: C:\projects\process mining\event logs\log1.csv
2024-08-11 20:03:35,839 ERROR: An error occurred while processing file: C:\projects\process mining\event logs\log1.csv 'Marking' object has no attribute 'apply'
Traceback (most recent call last):
  File "c:\projects\Process mining\test.py", line 70, in start_analyser
    bpmn_graph = bpmn_visualizer.apply(net, initial_marking, final_marking)
                 ^^^^^^^^^^^^^^^^^^^^^^^^^^^^^^^^^^^^^^^^^^^^^^^^^^^^^^^^^^
  File "C:\Users\it_su\AppData\Local\Packages\PythonSoftwareFoundation.Python.3.11_qbz5n2kfra8p0\LocalCache\local-packages\Python311\site-packages\pm4py\visualization\bpmn\visualizer.py", line 53, in apply
    return exec_utils.get_variant(variant).apply(bpmn_graph, parameters=parameters)
           ^^^^^^^^^^^^^^^^^^^^^^^^^^^^^^^^^^^^^
AttributeError: 'Marking' object has no attribute 'apply'

2024-08-11 20:32:51,021 ERROR: Analysed log path does not exist: C:\projects\process mining\event logs
2024-08-11 20:32:54,752 ERROR: Analysed log path does not exist: C:\projects\process mining\event logs
2024-08-11 20:49:33,795 ERROR: An error occurred while processing file : C:\projects\processMining\event logs\log1.csv unhashable type: 'list'
Traceback (most recent call last):
  File "c:\projects\ProcessMining\alpha_algo_app.py", line 120, in start_analyser
    traces_dict = read_log_file(chosen_file_name)
                  ^^^^^^^^^^^^^^^^^^^^^^^^^^^^^^^
  File "c:\projects\ProcessMining\alpha_algo_app.py", line 53, in read_log_file
    trace_dict = trace_counts.to_dict()
                 ^^^^^^^^^^^^^^^^^^^^^^
  File "C:\Users\it_su\AppData\Roaming\Python\Python312\site-packages\pandas\util\_decorators.py", line 333, in wrapper
    return func(*args, **kwargs)
           ^^^^^^^^^^^^^^^^^^^^^
  File "C:\Users\it_su\AppData\Roaming\Python\Python312\site-packages\pandas\core\series.py", line 2081, in to_dict
    return into_c(self.items())
           ^^^^^^^^^^^^^^^^^^^^
TypeError: unhashable type: 'list'

2024-08-11 20:49:45,818 ERROR: An error occurred while processing file : C:\projects\processMining\event logs\log1.csv unhashable type: 'list'
Traceback (most recent call last):
  File "c:\projects\ProcessMining\alpha_algo_app.py", line 120, in start_analyser
    traces_dict = read_log_file(chosen_file_name)
                  ^^^^^^^^^^^^^^^^^^^^^^^^^^^^^^^
  File "c:\projects\ProcessMining\alpha_algo_app.py", line 53, in read_log_file
    trace_dict = trace_counts.to_dict()
                 ^^^^^^^^^^^^^^^^^^^^^^
  File "C:\Users\it_su\AppData\Roaming\Python\Python312\site-packages\pandas\util\_decorators.py", line 333, in wrapper
    return func(*args, **kwargs)
           ^^^^^^^^^^^^^^^^^^^^^
  File "C:\Users\it_su\AppData\Roaming\Python\Python312\site-packages\pandas\core\series.py", line 2081, in to_dict
    return into_c(self.items())
           ^^^^^^^^^^^^^^^^^^^^
TypeError: unhashable type: 'list'

2024-08-11 21:29:02,668 ERROR: An error occurred while processing file : C:\projects\processMining\event logs\log1.csv name 'footprint' is not defined
Traceback (most recent call last):
  File "c:\projects\ProcessMining\alpha_algo_app.py", line 207, in start_analyser
    for pair, symbol in footprint.items():
                        ^^^^^^^^^
NameError: name 'footprint' is not defined

2024-08-11 21:58:28,160 ERROR: An error occurred while processing file : C:\projects\processMining\event logs\simplest_log.csv 'builtin_function_or_method' object is not subscriptable
Traceback (most recent call last):
  File "c:\projects\ProcessMining\alpha_algo_app.py", line 223, in start_analyser
    nodes = identify_all_nodes(traces_dict)
            ^^^^^^^^^^^^^^^^^^^^^^^^^^^^^^^
  File "c:\projects\ProcessMining\alpha_algo_app.py", line 83, in identify_all_nodes
    nodes.append['end']
    ~~~~~~~~~~~~^^^^^^^
TypeError: 'builtin_function_or_method' object is not subscriptable

2024-08-11 22:27:20,890 ERROR: An error occurred while processing file : C:\projects\processMining\event logs\simplest_log.csv eval() arg 1 must be a string, bytes or code object
Traceback (most recent call last):
  File "c:\projects\ProcessMining\alpha_algo_app.py", line 223, in start_analyser
    initial_events, final_events = identify_initial_and_final_events(traces_dict)
                                   ^^^^^^^^^^^^^^^^^^^^^^^^^^^^^^^^^^^^^^^^^^^^^^
  File "c:\projects\ProcessMining\alpha_algo_app.py", line 106, in identify_initial_and_final_events
    trace = eval(trace_str)
            ^^^^^^^^^^^^^^^
TypeError: eval() arg 1 must be a string, bytes or code object

2024-08-11 23:06:23,094 ERROR: An error occurred while processing file : C:\projects\processMining\event logs\simplest_log.csv eval() arg 1 must be a string, bytes or code object
Traceback (most recent call last):
  File "c:\projects\ProcessMining\alpha_algo_app.py", line 227, in start_analyser
    initial_events, final_events = identify_initial_and_final_events(traces_dict)
                                   ^^^^^^^^^^^^^^^^^^^^^^^^^^^^^^^^^^^^^^^^^^^^^^
  File "c:\projects\ProcessMining\alpha_algo_app.py", line 106, in identify_initial_and_final_events
    trace = eval(trace_str)
            ^^^^^^^^^^^^^^^
TypeError: eval() arg 1 must be a string, bytes or code object

2024-08-11 23:07:31,754 ERROR: An error occurred while processing file : C:\projects\processMining\event logs\simplest_log.csv compute_directly_follows() missing 2 required positional arguments: 'start_events' and 'end_events'
Traceback (most recent call last):
  File "c:\projects\ProcessMining\alpha_algo_app.py", line 228, in start_analyser
    directly_follows = compute_directly_follows(traces_dict)
                       ^^^^^^^^^^^^^^^^^^^^^^^^^^^^^^^^^^^^^
TypeError: compute_directly_follows() missing 2 required positional arguments: 'start_events' and 'end_events'

2024-08-12 01:00:49,691 ERROR: An error occurred while processing file : C:\projects\processMining\event logs\Insurance_claims_event_log.csv cannot access local variable 'relationships' where it is not associated with a value
Traceback (most recent call last):
  File "c:\projects\ProcessMining\alpha_algo_app.py", line 338, in start_analyser
    transitions = find_transitions(footprint,independent_sets)
                  ^^^^^^^^^^^^^^^^^^^^^^^^^^^^^^^^^^^^^^^^^^^^
  File "c:\projects\ProcessMining\alpha_algo_app.py", line 268, in find_transitions
    relationship = check_relationship(footprint_matrix, subset[0], subset[1])
                   ^^^^^^^^^^^^^^^^^^^^^^^^^^^^^^^^^^^^^^^^^^^^^^^^^^^^^^^^^^
  File "c:\projects\ProcessMining\alpha_algo_app.py", line 253, in check_relationship
    return relationships.pop() if len(relationships) == 1 else None
                                      ^^^^^^^^^^^^^
UnboundLocalError: cannot access local variable 'relationships' where it is not associated with a value

2024-08-12 01:23:28,410 ERROR: An error occurred while processing file : C:\projects\processMining\event logs\Insurance_claims_event_log.csv 'list' object cannot be interpreted as an integer
Traceback (most recent call last):
  File "c:\projects\ProcessMining\alpha_algo_app.py", line 346, in start_analyser
    transitions = find_transitions(footprint,independent_sets)
                  ^^^^^^^^^^^^^^^^^^^^^^^^^^^^^^^^^^^^^^^^^^^^
  File "c:\projects\ProcessMining\alpha_algo_app.py", line 269, in find_transitions
    for set_size in range (independent_sets):
                    ^^^^^^^^^^^^^^^^^^^^^^^^
TypeError: 'list' object cannot be interpreted as an integer

2024-08-12 01:24:31,542 ERROR: An error occurred while processing file : C:\projects\processMining\event logs\Insurance_claims_event_log.csv not enough values to unpack (expected 2, got 0)
Traceback (most recent call last):
  File "c:\projects\ProcessMining\alpha_algo_app.py", line 346, in start_analyser
    transitions = find_transitions(footprint,independent_sets)
                  ^^^^^^^^^^^^^^^^^^^^^^^^^^^^^^^^^^^^^^^^^^^^
  File "c:\projects\ProcessMining\alpha_algo_app.py", line 270, in find_transitions
    for set1, set2 in combinations(independent_sets, set_size):
        ^^^^^^^^^^
ValueError: not enough values to unpack (expected 2, got 0)

2024-08-12 01:25:20,151 ERROR: An error occurred while processing file : C:\projects\processMining\event logs\Insurance_claims_event_log.csv too many values to unpack (expected 2)
Traceback (most recent call last):
  File "c:\projects\ProcessMining\alpha_algo_app.py", line 346, in start_analyser
    transitions = find_transitions(footprint,independent_sets)
                  ^^^^^^^^^^^^^^^^^^^^^^^^^^^^^^^^^^^^^^^^^^^^
  File "c:\projects\ProcessMining\alpha_algo_app.py", line 270, in find_transitions
    for set1, set2 in combinations(independent_sets, set_size):
        ^^^^^^^^^^
ValueError: too many values to unpack (expected 2)

2024-08-12 02:12:11,428 ERROR: An error occurred while processing file : C:\projects\processMining\event logs\simplest_log.csv 'list' object has no attribute 'items'
Traceback (most recent call last):
  File "c:\projects\ProcessMining\alpha_algo_app.py", line 409, in start_analyser
    transitions = filter_maximal_sets(independent_sets)
                  ^^^^^^^^^^^^^^^^^^^^^^^^^^^^^^^^^^^^^
  File "c:\projects\ProcessMining\alpha_algo_app.py", line 323, in filter_maximal_sets
    pair_to_sets = map_pairs_to_sets(transitions)
                   ^^^^^^^^^^^^^^^^^^^^^^^^^^^^^^
  File "c:\projects\ProcessMining\alpha_algo_app.py", line 305, in map_pairs_to_sets
    for complex_set, _ in transitions.items():
                          ^^^^^^^^^^^^^^^^^
AttributeError: 'list' object has no attribute 'items'

2024-08-12 02:29:12,912 ERROR: An error occurred while processing file : C:\projects\processMining\event logs\simplest_log.csv name 'product' is not defined
Traceback (most recent call last):
  File "c:\projects\ProcessMining\alpha_algo_app.py", line 406, in start_analyser
    filtered_transitions = filter_maximal_sets(transitions)
                           ^^^^^^^^^^^^^^^^^^^^^^^^^^^^^^^^
  File "c:\projects\ProcessMining\alpha_algo_app.py", line 319, in filter_maximal_sets
    pair_to_sets = map_pairs_to_sets(transitions)
                   ^^^^^^^^^^^^^^^^^^^^^^^^^^^^^^
  File "c:\projects\ProcessMining\alpha_algo_app.py", line 301, in map_pairs_to_sets
    pairs = deconstruct_subset(complex_set)
            ^^^^^^^^^^^^^^^^^^^^^^^^^^^^^^^
  File "c:\projects\ProcessMining\alpha_algo_app.py", line 286, in deconstruct_subset
    return set(product(set1, set2))
               ^^^^^^^
NameError: name 'product' is not defined

2024-08-12 09:31:39,747 ERROR: An error occurred while processing file: Insurance_claims_event_log.csv name 'graphviz' is not defined
Traceback (most recent call last):
  File "C:\projects\ProcessMining\test_with_graphics.py", line 141, in start_analyser
    display_traces_table(traces_dict)
  File "C:\projects\ProcessMining\test_with_graphics.py", line 78, in display_traces_table
    dot = graphviz.Digraph(format='png')
          ^^^^^^^^
NameError: name 'graphviz' is not defined

2024-08-12 10:08:37,469 ERROR: An error occurred while processing file: Insurance_claims_event_log.csv 1 columns passed, passed data had 2 columns
Traceback (most recent call last):
  File "C:\projects\ProcessMining\pm-training-alpha-miner\streamlit\Lib\site-packages\pandas\core\internals\construction.py", line 939, in _finalize_columns_and_data
    columns = _validate_or_indexify_columns(contents, columns)
              ^^^^^^^^^^^^^^^^^^^^^^^^^^^^^^^^^^^^^^^^^^^^^^^^
  File "C:\projects\ProcessMining\pm-training-alpha-miner\streamlit\Lib\site-packages\pandas\core\internals\construction.py", line 986, in _validate_or_indexify_columns
    raise AssertionError(
AssertionError: 1 columns passed, passed data had 2 columns

The above exception was the direct cause of the following exception:

Traceback (most recent call last):
  File "C:\projects\ProcessMining\test_with_graphics.py", line 199, in start_analyser
    display_single_column_table(independent_sets, 'Independent Sets', 'Independent Sets')
  File "C:\projects\ProcessMining\test_with_graphics.py", line 143, in display_single_column_table
    df = pd.DataFrame(data, columns=[column_name])
         ^^^^^^^^^^^^^^^^^^^^^^^^^^^^^^^^^^^^^^^^^
  File "C:\projects\ProcessMining\pm-training-alpha-miner\streamlit\Lib\site-packages\pandas\core\frame.py", line 851, in __init__
    arrays, columns, index = nested_data_to_arrays(
                             ^^^^^^^^^^^^^^^^^^^^^^
  File "C:\projects\ProcessMining\pm-training-alpha-miner\streamlit\Lib\site-packages\pandas\core\internals\construction.py", line 520, in nested_data_to_arrays
    arrays, columns = to_arrays(data, columns, dtype=dtype)
                      ^^^^^^^^^^^^^^^^^^^^^^^^^^^^^^^^^^^^^
  File "C:\projects\ProcessMining\pm-training-alpha-miner\streamlit\Lib\site-packages\pandas\core\internals\construction.py", line 845, in to_arrays
    content, columns = _finalize_columns_and_data(arr, columns, dtype)
                       ^^^^^^^^^^^^^^^^^^^^^^^^^^^^^^^^^^^^^^^^^^^^^^^
  File "C:\projects\ProcessMining\pm-training-alpha-miner\streamlit\Lib\site-packages\pandas\core\internals\construction.py", line 942, in _finalize_columns_and_data
    raise ValueError(err) from err
ValueError: 1 columns passed, passed data had 2 columns

2024-08-12 10:18:19,352 ERROR: An error occurred while processing file: Insurance_claims_event_log.csv 'list' object has no attribute 'items'
Traceback (most recent call last):
  File "C:\projects\ProcessMining\test_with_graphics.py", line 222, in start_analyser
    independent_sets_tuples = list(independent_sets.items())
                                   ^^^^^^^^^^^^^^^^^^^^^^
AttributeError: 'list' object has no attribute 'items'

2024-08-12 11:03:07,473 ERROR: An error occurred while processing file : C:\projects\processMining\event logs\Insurance_claims_event_log.csv 'BpmnDiagramGraph' object has no attribute 'add_start_event'
Traceback (most recent call last):
  File "c:\projects\ProcessMining\alpha_algo_app.py", line 483, in start_analyser
    bpmn_xml = create_bpmn_model(initial_events, final_events, nodes, filtered_transitions)
               ^^^^^^^^^^^^^^^^^^^^^^^^^^^^^^^^^^^^^^^^^^^^^^^^^^^^^^^^^^^^^^^^^^^^^^^^^^^^
  File "c:\projects\ProcessMining\alpha_algo_app.py", line 369, in create_bpmn_model
    bpmn.add_start_event(event)
    ^^^^^^^^^^^^^^^^^^^^
AttributeError: 'BpmnDiagramGraph' object has no attribute 'add_start_event'

2024-08-12 11:06:57,448 ERROR: An error occurred while processing file : C:\projects\processMining\event logs\Insurance_claims_event_log.csv 'Graph' object has no attribute 'node'
Traceback (most recent call last):
  File "c:\projects\ProcessMining\alpha_algo_app.py", line 487, in start_analyser
    bpmn_xml = create_bpmn_model(initial_events, final_events, nodes, filtered_transitions)
               ^^^^^^^^^^^^^^^^^^^^^^^^^^^^^^^^^^^^^^^^^^^^^^^^^^^^^^^^^^^^^^^^^^^^^^^^^^^^
  File "c:\projects\ProcessMining\alpha_algo_app.py", line 377, in create_bpmn_model
    bpmn_graph.add_start_event_to_diagram(process_id, node_id, event, "")
  File "C:\Users\it_su\AppData\Roaming\Python\Python312\site-packages\bpmn_python\bpmn_diagram_rep.py", line 324, in add_start_event_to_diagram
    start_event_id, start_event = self.add_flow_node_to_diagram(process_id, consts.Consts.start_event,
                                  ^^^^^^^^^^^^^^^^^^^^^^^^^^^^^^^^^^^^^^^^^^^^^^^^^^^^^^^^^^^^^^^^^^^^
  File "C:\Users\it_su\AppData\Roaming\Python\Python312\site-packages\bpmn_python\bpmn_diagram_rep.py", line 254, in add_flow_node_to_diagram
    self.diagram_graph.node[node_id][consts.Consts.id] = node_id
    ^^^^^^^^^^^^^^^^^^^^^^^
AttributeError: 'Graph' object has no attribute 'node'. Did you mean: '_node'?

2024-08-12 11:12:16,660 ERROR: An error occurred while processing file : C:\projects\processMining\event logs\Insurance_claims_event_log.csv 'BpmnDiagramGraph' object has no attribute 'add_flownode_to_diagram'
Traceback (most recent call last):
  File "c:\projects\ProcessMining\alpha_algo_app.py", line 488, in start_analyser
    bpmn_xml = create_bpmn_model(initial_events, final_events, nodes, filtered_transitions)
               ^^^^^^^^^^^^^^^^^^^^^^^^^^^^^^^^^^^^^^^^^^^^^^^^^^^^^^^^^^^^^^^^^^^^^^^^^^^^
  File "c:\projects\ProcessMining\alpha_algo_app.py", line 379, in create_bpmn_model
    bpmn_graph.add_flownode_to_diagram(process_id, node_id, event, bpmn.Consts.start_event)
    ^^^^^^^^^^^^^^^^^^^^^^^^^^^^^^^^^^
AttributeError: 'BpmnDiagramGraph' object has no attribute 'add_flownode_to_diagram'. Did you mean: 'add_flow_node_to_diagram'?

2024-08-12 11:15:00,881 ERROR: An error occurred while processing file : C:\projects\processMining\event logs\Insurance_claims_event_log.csv module 'bpmn_python.bpmn_diagram_rep' has no attribute 'Consts'
Traceback (most recent call last):
  File "c:\projects\ProcessMining\alpha_algo_app.py", line 486, in start_analyser
    bpmn_xml = create_bpmn_model(initial_events, final_events, nodes, filtered_transitions)
               ^^^^^^^^^^^^^^^^^^^^^^^^^^^^^^^^^^^^^^^^^^^^^^^^^^^^^^^^^^^^^^^^^^^^^^^^^^^^
  File "c:\projects\ProcessMining\alpha_algo_app.py", line 376, in create_bpmn_model
    bpmn_graph.add_flow_node_to_diagram(process_id, node_id, event, bpmn.Consts.start_event)
                                                                    ^^^^^^^^^^^
AttributeError: module 'bpmn_python.bpmn_diagram_rep' has no attribute 'Consts'. Did you mean: 'consts'?

2024-08-12 11:15:43,139 ERROR: An error occurred while processing file : C:\projects\processMining\event logs\Insurance_claims_event_log.csv module 'bpmn_python.bpmn_python_consts' has no attribute 'start_event'
Traceback (most recent call last):
  File "c:\projects\ProcessMining\alpha_algo_app.py", line 486, in start_analyser
    bpmn_xml = create_bpmn_model(initial_events, final_events, nodes, filtered_transitions)
               ^^^^^^^^^^^^^^^^^^^^^^^^^^^^^^^^^^^^^^^^^^^^^^^^^^^^^^^^^^^^^^^^^^^^^^^^^^^^
  File "c:\projects\ProcessMining\alpha_algo_app.py", line 376, in create_bpmn_model
    bpmn_graph.add_flow_node_to_diagram(process_id, node_id, event, bpmn.consts.start_event)
                                                                    ^^^^^^^^^^^^^^^^^^^^^^^
AttributeError: module 'bpmn_python.bpmn_python_consts' has no attribute 'start_event'

2024-08-12 11:20:31,302 ERROR: An error occurred while processing file : C:\projects\processMining\event logs\Insurance_claims_event_log.csv 'Graph' object has no attribute 'node'
Traceback (most recent call last):
  File "c:\projects\ProcessMining\alpha_algo_app.py", line 487, in start_analyser
    bpmn_xml = create_bpmn_model(initial_events, final_events, nodes, filtered_transitions)
               ^^^^^^^^^^^^^^^^^^^^^^^^^^^^^^^^^^^^^^^^^^^^^^^^^^^^^^^^^^^^^^^^^^^^^^^^^^^^
  File "c:\projects\ProcessMining\alpha_algo_app.py", line 377, in create_bpmn_model
    bpmn_graph.add_start_event_to_diagram(process_id, node_id, event)
  File "C:\Users\it_su\AppData\Roaming\Python\Python312\site-packages\bpmn_python\bpmn_diagram_rep.py", line 324, in add_start_event_to_diagram
    start_event_id, start_event = self.add_flow_node_to_diagram(process_id, consts.Consts.start_event,
                                  ^^^^^^^^^^^^^^^^^^^^^^^^^^^^^^^^^^^^^^^^^^^^^^^^^^^^^^^^^^^^^^^^^^^^
  File "C:\Users\it_su\AppData\Roaming\Python\Python312\site-packages\bpmn_python\bpmn_diagram_rep.py", line 254, in add_flow_node_to_diagram
    self.diagram_graph.node[node_id][consts.Consts.id] = node_id
    ^^^^^^^^^^^^^^^^^^^^^^^
AttributeError: 'Graph' object has no attribute 'node'. Did you mean: '_node'?

2024-08-12 11:20:38,335 ERROR: An error occurred while processing file : C:\projects\processMining\event logs\Insurance_claims_event_log.csv 'Graph' object has no attribute 'node'
Traceback (most recent call last):
  File "c:\projects\ProcessMining\alpha_algo_app.py", line 487, in start_analyser
    bpmn_xml = create_bpmn_model(initial_events, final_events, nodes, filtered_transitions)
               ^^^^^^^^^^^^^^^^^^^^^^^^^^^^^^^^^^^^^^^^^^^^^^^^^^^^^^^^^^^^^^^^^^^^^^^^^^^^
  File "c:\projects\ProcessMining\alpha_algo_app.py", line 377, in create_bpmn_model
    bpmn_graph.add_start_event_to_diagram(process_id, node_id, event)
  File "C:\Users\it_su\AppData\Roaming\Python\Python312\site-packages\bpmn_python\bpmn_diagram_rep.py", line 324, in add_start_event_to_diagram
    start_event_id, start_event = self.add_flow_node_to_diagram(process_id, consts.Consts.start_event,
                                  ^^^^^^^^^^^^^^^^^^^^^^^^^^^^^^^^^^^^^^^^^^^^^^^^^^^^^^^^^^^^^^^^^^^^
  File "C:\Users\it_su\AppData\Roaming\Python\Python312\site-packages\bpmn_python\bpmn_diagram_rep.py", line 254, in add_flow_node_to_diagram
    self.diagram_graph.node[node_id][consts.Consts.id] = node_id
    ^^^^^^^^^^^^^^^^^^^^^^^
AttributeError: 'Graph' object has no attribute 'node'. Did you mean: '_node'?

2024-08-12 12:17:09,866 ERROR: An error occurred while processing file : C:\projects\processMining\event logs\Insurance_claims_event_log.csv 'Graph' object has no attribute 'node'
Traceback (most recent call last):
  File "c:\projects\ProcessMining\alpha_algo_app.py", line 487, in start_analyser
    bpmn_xml = create_bpmn_model(initial_events, final_events, nodes, filtered_transitions)
               ^^^^^^^^^^^^^^^^^^^^^^^^^^^^^^^^^^^^^^^^^^^^^^^^^^^^^^^^^^^^^^^^^^^^^^^^^^^^
  File "c:\projects\ProcessMining\alpha_algo_app.py", line 377, in create_bpmn_model
    bpmn_graph.add_start_event_to_diagram(process_id, node_id, event)
  File "C:\projects\ProcessMining\pm-training-alpha-miner\streamlit\Lib\site-packages\bpmn_python\bpmn_diagram_rep.py", line 324, in add_start_event_to_diagram
    start_event_id, start_event = self.add_flow_node_to_diagram(process_id, consts.Consts.start_event,
                                  ^^^^^^^^^^^^^^^^^^^^^^^^^^^^^^^^^^^^^^^^^^^^^^^^^^^^^^^^^^^^^^^^^^^^
  File "C:\projects\ProcessMining\pm-training-alpha-miner\streamlit\Lib\site-packages\bpmn_python\bpmn_diagram_rep.py", line 254, in add_flow_node_to_diagram
    self.diagram_graph.node[node_id][consts.Consts.id] = node_id
    ^^^^^^^^^^^^^^^^^^^^^^^
AttributeError: 'Graph' object has no attribute 'node'. Did you mean: '_node'?

2024-08-12 12:22:30,109 ERROR: An error occurred while processing file : C:\projects\processMining\event logs\Insurance_claims_event_log.csv 'Graph' object has no attribute 'node'
Traceback (most recent call last):
  File "c:\projects\ProcessMining\alpha_algo_app.py", line 487, in start_analyser
    bpmn_xml = create_bpmn_model(initial_events, final_events, nodes, filtered_transitions)
               ^^^^^^^^^^^^^^^^^^^^^^^^^^^^^^^^^^^^^^^^^^^^^^^^^^^^^^^^^^^^^^^^^^^^^^^^^^^^
  File "c:\projects\ProcessMining\alpha_algo_app.py", line 377, in create_bpmn_model
    bpmn_graph.add_start_event_to_diagram(process_id, node_id, event)
  File "C:\Users\it_su\AppData\Roaming\Python\Python312\site-packages\bpmn_python\bpmn_diagram_rep.py", line 324, in add_start_event_to_diagram
    start_event_id, start_event = self.add_flow_node_to_diagram(process_id, consts.Consts.start_event,
                                  ^^^^^^^^^^^^^^^^^^^^^^^^^^^^^^^^^^^^^^^^^^^^^^^^^^^^^^^^^^^^^^^^^^^^
  File "C:\Users\it_su\AppData\Roaming\Python\Python312\site-packages\bpmn_python\bpmn_diagram_rep.py", line 254, in add_flow_node_to_diagram
    self.diagram_graph.node[node_id][consts.Consts.id] = node_id
    ^^^^^^^^^^^^^^^^^^^^^^^
AttributeError: 'Graph' object has no attribute 'node'. Did you mean: '_node'?

2024-08-12 12:22:38,806 ERROR: An error occurred while processing file : C:\projects\processMining\event logs\Insurance_claims_event_log.csv 'Graph' object has no attribute 'node'
Traceback (most recent call last):
  File "c:\projects\ProcessMining\alpha_algo_app.py", line 487, in start_analyser
    bpmn_xml = create_bpmn_model(initial_events, final_events, nodes, filtered_transitions)
               ^^^^^^^^^^^^^^^^^^^^^^^^^^^^^^^^^^^^^^^^^^^^^^^^^^^^^^^^^^^^^^^^^^^^^^^^^^^^
  File "c:\projects\ProcessMining\alpha_algo_app.py", line 377, in create_bpmn_model
    bpmn_graph.add_start_event_to_diagram(process_id, node_id, event)
  File "C:\projects\ProcessMining\pm-training-alpha-miner\streamlit\Lib\site-packages\bpmn_python\bpmn_diagram_rep.py", line 324, in add_start_event_to_diagram
    start_event_id, start_event = self.add_flow_node_to_diagram(process_id, consts.Consts.start_event,
                                  ^^^^^^^^^^^^^^^^^^^^^^^^^^^^^^^^^^^^^^^^^^^^^^^^^^^^^^^^^^^^^^^^^^^^
  File "C:\projects\ProcessMining\pm-training-alpha-miner\streamlit\Lib\site-packages\bpmn_python\bpmn_diagram_rep.py", line 254, in add_flow_node_to_diagram
    self.diagram_graph.node[node_id][consts.Consts.id] = node_id
    ^^^^^^^^^^^^^^^^^^^^^^^
AttributeError: 'Graph' object has no attribute 'node'. Did you mean: '_node'?

2024-08-12 12:56:08,229 ERROR: An error occurred while processing file : C:\projects\processMining\event logs\log2.csv can only concatenate str (not "int") to str
Traceback (most recent call last):
  File "c:\projects\ProcessMining\alpha_algo_app.py", line 543, in start_analyser
    categorized_transitions = classify_transitions(filtered_transitions)
                              ^^^^^^^^^^^^^^^^^^^^^^^^^^^^^^^^^^^^^^^^^^
  File "c:\projects\ProcessMining\alpha_algo_app.py", line 475, in classify_transitions
    transition_categories[source + target] = exit_gateway_id +"_" + counter_id
                                             ~~~~~~~~~~~~~~~~~~~~~^~~~~~~~~~~~
TypeError: can only concatenate str (not "int") to str

2024-08-12 16:08:41,598 ERROR: An error occurred while processing file : C:\projects\processMining\event logs\log2.csv 'f'
Traceback (most recent call last):
  File "c:\projects\ProcessMining\alpha_algo_app.py", line 571, in start_analyser
    categorized_transitions = classify_transitions(filtered_transitions)
                              ^^^^^^^^^^^^^^^^^^^^^^^^^^^^^^^^^^^^^^^^^^
  File "c:\projects\ProcessMining\alpha_algo_app.py", line 461, in classify_transitions
    if not gateway_entries[node] :
           ~~~~~~~~~~~~~~~^^^^^^
KeyError: 'f'

2024-08-12 16:10:04,614 ERROR: An error occurred while processing file : C:\projects\processMining\event logs\log2.csv 'd'
Traceback (most recent call last):
  File "c:\projects\ProcessMining\alpha_algo_app.py", line 571, in start_analyser
    categorized_transitions = classify_transitions(filtered_transitions)
                              ^^^^^^^^^^^^^^^^^^^^^^^^^^^^^^^^^^^^^^^^^^
  File "c:\projects\ProcessMining\alpha_algo_app.py", line 461, in classify_transitions
    if gateway_entries[node] == None :
      ~~~~~~~~~~~~~~~^^^^^^
KeyError: 'd'

2024-08-12 16:28:34,656 ERROR: An error occurred while processing file: Insurance_claims_event_log.csv expected string or bytes-like object, got 'bool'
Traceback (most recent call last):
  File "C:\projects\ProcessMining\test_with_graphics.py", line 318, in start_analyser
    diagram_path = create_bpmn_diagram(initial_events, final_events, nodes, categorized_transitions)
                   ^^^^^^^^^^^^^^^^^^^^^^^^^^^^^^^^^^^^^^^^^^^^^^^^^^^^^^^^^^^^^^^^^^^^^^^^^^^^^^^^^
  File "C:\projects\ProcessMining\test_with_graphics.py", line 244, in create_bpmn_diagram
    dot.edge(str(source), str(target), label=condition if condition else '')
  File "C:\projects\ProcessMining\pm-training-alpha-miner\streamlit\Lib\site-packages\graphviz\_tools.py", line 171, in wrapper
    return func(*args, **kwargs)
           ^^^^^^^^^^^^^^^^^^^^^
  File "C:\projects\ProcessMining\pm-training-alpha-miner\streamlit\Lib\site-packages\graphviz\dot.py", line 234, in edge
    attr_list = self._attr_list(label, kwargs=attrs, attributes=_attributes)
                ^^^^^^^^^^^^^^^^^^^^^^^^^^^^^^^^^^^^^^^^^^^^^^^^^^^^^^^^^^^^
  File "C:\projects\ProcessMining\pm-training-alpha-miner\streamlit\Lib\site-packages\graphviz\_tools.py", line 171, in wrapper
    return func(*args, **kwargs)
           ^^^^^^^^^^^^^^^^^^^^^
  File "C:\projects\ProcessMining\pm-training-alpha-miner\streamlit\Lib\site-packages\graphviz\quoting.py", line 152, in attr_list
    content = a_list(label, kwargs=kwargs, attributes=attributes)
              ^^^^^^^^^^^^^^^^^^^^^^^^^^^^^^^^^^^^^^^^^^^^^^^^^^^
  File "C:\projects\ProcessMining\pm-training-alpha-miner\streamlit\Lib\site-packages\graphviz\_tools.py", line 171, in wrapper
    return func(*args, **kwargs)
           ^^^^^^^^^^^^^^^^^^^^^
  File "C:\projects\ProcessMining\pm-training-alpha-miner\streamlit\Lib\site-packages\graphviz\quoting.py", line 123, in a_list
    result = [f'label={quote(label)}'] if label is not None else []
                       ^^^^^^^^^^^^
  File "C:\projects\ProcessMining\pm-training-alpha-miner\streamlit\Lib\site-packages\graphviz\_tools.py", line 171, in wrapper
    return func(*args, **kwargs)
           ^^^^^^^^^^^^^^^^^^^^^
  File "C:\projects\ProcessMining\pm-training-alpha-miner\streamlit\Lib\site-packages\graphviz\quoting.py", line 82, in quote
    if is_html_string(identifier) and not isinstance(identifier, NoHtml):
       ^^^^^^^^^^^^^^^^^^^^^^^^^^
TypeError: expected string or bytes-like object, got 'bool'

2024-08-12 16:35:12,487 ERROR: An error occurred while processing file: Insurance_claims_event_log.csv expected string or bytes-like object, got 'bool'
Traceback (most recent call last):
  File "C:\projects\ProcessMining\test_with_graphics.py", line 319, in start_analyser
    diagram_path = create_bpmn_diagram(initial_events, final_events, nodes, categorized_transitions)
                   ^^^^^^^^^^^^^^^^^^^^^^^^^^^^^^^^^^^^^^^^^^^^^^^^^^^^^^^^^^^^^^^^^^^^^^^^^^^^^^^^^
  File "C:\projects\ProcessMining\test_with_graphics.py", line 245, in create_bpmn_diagram
    dot.edge(source, target, label=condition if condition else '')
  File "C:\projects\ProcessMining\pm-training-alpha-miner\streamlit\Lib\site-packages\graphviz\_tools.py", line 171, in wrapper
    return func(*args, **kwargs)
           ^^^^^^^^^^^^^^^^^^^^^
  File "C:\projects\ProcessMining\pm-training-alpha-miner\streamlit\Lib\site-packages\graphviz\dot.py", line 234, in edge
    attr_list = self._attr_list(label, kwargs=attrs, attributes=_attributes)
                ^^^^^^^^^^^^^^^^^^^^^^^^^^^^^^^^^^^^^^^^^^^^^^^^^^^^^^^^^^^^
  File "C:\projects\ProcessMining\pm-training-alpha-miner\streamlit\Lib\site-packages\graphviz\_tools.py", line 171, in wrapper
    return func(*args, **kwargs)
           ^^^^^^^^^^^^^^^^^^^^^
  File "C:\projects\ProcessMining\pm-training-alpha-miner\streamlit\Lib\site-packages\graphviz\quoting.py", line 152, in attr_list
    content = a_list(label, kwargs=kwargs, attributes=attributes)
              ^^^^^^^^^^^^^^^^^^^^^^^^^^^^^^^^^^^^^^^^^^^^^^^^^^^
  File "C:\projects\ProcessMining\pm-training-alpha-miner\streamlit\Lib\site-packages\graphviz\_tools.py", line 171, in wrapper
    return func(*args, **kwargs)
           ^^^^^^^^^^^^^^^^^^^^^
  File "C:\projects\ProcessMining\pm-training-alpha-miner\streamlit\Lib\site-packages\graphviz\quoting.py", line 123, in a_list
    result = [f'label={quote(label)}'] if label is not None else []
                       ^^^^^^^^^^^^
  File "C:\projects\ProcessMining\pm-training-alpha-miner\streamlit\Lib\site-packages\graphviz\_tools.py", line 171, in wrapper
    return func(*args, **kwargs)
           ^^^^^^^^^^^^^^^^^^^^^
  File "C:\projects\ProcessMining\pm-training-alpha-miner\streamlit\Lib\site-packages\graphviz\quoting.py", line 82, in quote
    if is_html_string(identifier) and not isinstance(identifier, NoHtml):
       ^^^^^^^^^^^^^^^^^^^^^^^^^^
TypeError: expected string or bytes-like object, got 'bool'

2024-08-12 19:04:58,627 ERROR: An error occurred while processing file: simplest_log.csv too many values to unpack (expected 2)
Traceback (most recent call last):
  File "C:\projects\ProcessMining\test_with_graphics.py", line 372, in start_analyser
    diagram_path = create_petri_net(initial_events, final_events, nodes, categorized_transitions)
                   ^^^^^^^^^^^^^^^^^^^^^^^^^^^^^^^^^^^^^^^^^^^^^^^^^^^^^^^^^^^^^^^^^^^^^^^^^^^^^^
  File "C:\projects\ProcessMining\test_with_graphics.py", line 278, in create_petri_net
    for (source, target), relationship in filtered_transitions.items():
        ^^^^^^^^^^^^^^^^
ValueError: too many values to unpack (expected 2)

2024-08-12 19:15:46,913 ERROR: An error occurred while processing file: log5.csv tuple indices must be integers or slices, not str
Traceback (most recent call last):
  File "C:\projects\ProcessMining\test_with_graphics.py", line 374, in start_analyser
    diagram_path = create_petri_net(initial_events, final_events, nodes, filtered_transitions)
                   ^^^^^^^^^^^^^^^^^^^^^^^^^^^^^^^^^^^^^^^^^^^^^^^^^^^^^^^^^^^^^^^^^^^^^^^^^^^
  File "C:\projects\ProcessMining\test_with_graphics.py", line 293, in create_petri_net
    dot.edge(source[node], transition_id)
             ~~~~~~^^^^^^
TypeError: tuple indices must be integers or slices, not str

2024-08-12 19:16:15,345 ERROR: An error occurred while processing file: log5.csv tuple indices must be integers or slices, not str
Traceback (most recent call last):
  File "C:\projects\ProcessMining\test_with_graphics.py", line 374, in start_analyser
    diagram_path = create_petri_net(initial_events, final_events, nodes, filtered_transitions)
                   ^^^^^^^^^^^^^^^^^^^^^^^^^^^^^^^^^^^^^^^^^^^^^^^^^^^^^^^^^^^^^^^^^^^^^^^^^^^
  File "C:\projects\ProcessMining\test_with_graphics.py", line 293, in create_petri_net
    dot.edge(source[i], transition_id)
             ~~~~~~^^^
TypeError: tuple indices must be integers or slices, not str

2024-08-12 19:30:51,717 ERROR: An error occurred while processing file: log1.csv name 'create_petri_net' is not defined
Traceback (most recent call last):
  File "C:\projects\ProcessMining\test_with_graphics.py", line 418, in start_analyser
    diagram_path = create_petri_net(initial_events, final_events, nodes, filtered_transitions)
                   ^^^^^^^^^^^^^^^^
NameError: name 'create_petri_net' is not defined

2024-08-12 19:31:27,965 ERROR: An error occurred while processing file: log1.csv 'NoneType' object has no attribute 'format'
Traceback (most recent call last):
  File "C:\projects\ProcessMining\test_with_graphics.py", line 421, in start_analyser
    st.image(diagram_path, caption='Petri-Net Diagram', use_column_width=False)
  File "C:\projects\ProcessMining\pm-training-alpha-miner\streamlit\Lib\site-packages\streamlit\runtime\metrics_util.py", line 408, in wrapped_func
    result = non_optional_func(*args, **kwargs)
             ^^^^^^^^^^^^^^^^^^^^^^^^^^^^^^^^^^
  File "C:\projects\ProcessMining\pm-training-alpha-miner\streamlit\Lib\site-packages\streamlit\elements\image.py", line 161, in image
    marshall_images(
  File "C:\projects\ProcessMining\pm-training-alpha-miner\streamlit\Lib\site-packages\streamlit\elements\image.py", line 551, in marshall_images
    proto_img.url = image_to_url(
                    ^^^^^^^^^^^^^
  File "C:\projects\ProcessMining\pm-training-alpha-miner\streamlit\Lib\site-packages\streamlit\elements\image.py", line 443, in image_to_url
    image_format = _validate_image_format_string(image_data, output_format)
                   ^^^^^^^^^^^^^^^^^^^^^^^^^^^^^^^^^^^^^^^^^^^^^^^^^^^^^^^^
  File "C:\projects\ProcessMining\pm-training-alpha-miner\streamlit\Lib\site-packages\streamlit\elements\image.py", line 216, in _validate_image_format_string
    if _image_is_gif(pil_image):
       ^^^^^^^^^^^^^^^^^^^^^^^^
  File "C:\projects\ProcessMining\pm-training-alpha-miner\streamlit\Lib\site-packages\streamlit\elements\image.py", line 187, in _image_is_gif
    return bool(image.format == "GIF")
                ^^^^^^^^^^^^
AttributeError: 'NoneType' object has no attribute 'format'

2024-08-12 19:31:37,575 ERROR: An error occurred while processing file: simplest_log.csv 'NoneType' object has no attribute 'format'
Traceback (most recent call last):
  File "C:\projects\ProcessMining\test_with_graphics.py", line 421, in start_analyser
    st.image(diagram_path, caption='Petri-Net Diagram', use_column_width=False)
  File "C:\projects\ProcessMining\pm-training-alpha-miner\streamlit\Lib\site-packages\streamlit\runtime\metrics_util.py", line 408, in wrapped_func
    result = non_optional_func(*args, **kwargs)
             ^^^^^^^^^^^^^^^^^^^^^^^^^^^^^^^^^^
  File "C:\projects\ProcessMining\pm-training-alpha-miner\streamlit\Lib\site-packages\streamlit\elements\image.py", line 161, in image
    marshall_images(
  File "C:\projects\ProcessMining\pm-training-alpha-miner\streamlit\Lib\site-packages\streamlit\elements\image.py", line 551, in marshall_images
    proto_img.url = image_to_url(
                    ^^^^^^^^^^^^^
  File "C:\projects\ProcessMining\pm-training-alpha-miner\streamlit\Lib\site-packages\streamlit\elements\image.py", line 443, in image_to_url
    image_format = _validate_image_format_string(image_data, output_format)
                   ^^^^^^^^^^^^^^^^^^^^^^^^^^^^^^^^^^^^^^^^^^^^^^^^^^^^^^^^
  File "C:\projects\ProcessMining\pm-training-alpha-miner\streamlit\Lib\site-packages\streamlit\elements\image.py", line 216, in _validate_image_format_string
    if _image_is_gif(pil_image):
       ^^^^^^^^^^^^^^^^^^^^^^^^
  File "C:\projects\ProcessMining\pm-training-alpha-miner\streamlit\Lib\site-packages\streamlit\elements\image.py", line 187, in _image_is_gif
    return bool(image.format == "GIF")
                ^^^^^^^^^^^^
AttributeError: 'NoneType' object has no attribute 'format'

2024-08-12 19:33:08,743 ERROR: An error occurred while processing file: Insurance_claims_event_log.csv 'NoneType' object has no attribute 'format'
Traceback (most recent call last):
  File "C:\projects\ProcessMining\test_with_graphics.py", line 421, in start_analyser
    st.image(diagram_path, caption='Petri-Net Diagram', use_column_width=False)
  File "C:\projects\ProcessMining\pm-training-alpha-miner\streamlit\Lib\site-packages\streamlit\runtime\metrics_util.py", line 408, in wrapped_func
    result = non_optional_func(*args, **kwargs)
             ^^^^^^^^^^^^^^^^^^^^^^^^^^^^^^^^^^
  File "C:\projects\ProcessMining\pm-training-alpha-miner\streamlit\Lib\site-packages\streamlit\elements\image.py", line 161, in image
    marshall_images(
  File "C:\projects\ProcessMining\pm-training-alpha-miner\streamlit\Lib\site-packages\streamlit\elements\image.py", line 551, in marshall_images
    proto_img.url = image_to_url(
                    ^^^^^^^^^^^^^
  File "C:\projects\ProcessMining\pm-training-alpha-miner\streamlit\Lib\site-packages\streamlit\elements\image.py", line 443, in image_to_url
    image_format = _validate_image_format_string(image_data, output_format)
                   ^^^^^^^^^^^^^^^^^^^^^^^^^^^^^^^^^^^^^^^^^^^^^^^^^^^^^^^^
  File "C:\projects\ProcessMining\pm-training-alpha-miner\streamlit\Lib\site-packages\streamlit\elements\image.py", line 216, in _validate_image_format_string
    if _image_is_gif(pil_image):
       ^^^^^^^^^^^^^^^^^^^^^^^^
  File "C:\projects\ProcessMining\pm-training-alpha-miner\streamlit\Lib\site-packages\streamlit\elements\image.py", line 187, in _image_is_gif
    return bool(image.format == "GIF")
                ^^^^^^^^^^^^
AttributeError: 'NoneType' object has no attribute 'format'

2024-08-12 20:16:48,214 ERROR: An error occurred while processing file: None join() argument must be str, bytes, or os.PathLike object, not 'NoneType'
Traceback (most recent call last):
  File "C:\projects\ProcessMining\test_with_graphics.py", line 413, in start_analyser
    traces_dict = alpha_algo_app.read_log_file(selected_file)
                  ^^^^^^^^^^^^^^^^^^^^^^^^^^^^^^^^^^^^^^^^^^^
  File "c:\projects\ProcessMining\alpha_algo_app.py", line 40, in read_log_file
    analysed_log = os.path.join(param['analysed_log_path'], analysed_file_name)
                   ^^^^^^^^^^^^^^^^^^^^^^^^^^^^^^^^^^^^^^^^^^^^^^^^^^^^^^^^^^^^
  File "<frozen ntpath>", line 149, in join
  File "<frozen genericpath>", line 164, in _check_arg_types
TypeError: join() argument must be str, bytes, or os.PathLike object, not 'NoneType'

2024-08-12 22:17:17,086 ERROR: An error occurred while processing file: Insurance_claims_event_log.csv name 'display_traces_table' is not defined
Traceback (most recent call last):
  File "C:\projects\ProcessMining\test_with_graphics.py", line 148, in start_analyser
    display_traces_table(traces_dict)
    ^^^^^^^^^^^^^^^^^^^^
NameError: name 'display_traces_table' is not defined

2024-08-12 22:18:31,409 ERROR: An error occurred while processing file: Insurance_claims_event_log.csv name 'display_traces_table' is not defined
Traceback (most recent call last):
  File "C:\projects\ProcessMining\test_with_graphics.py", line 148, in start_analyser
    display_traces_table(traces_dict)
    ^^^^^^^^^^^^^^^^^^^^
NameError: name 'display_traces_table' is not defined

2024-08-12 22:20:01,511 ERROR: An error occurred while processing file: Insurance_claims_event_log.csv name 'display_single_column_table' is not defined
Traceback (most recent call last):
  File "C:\projects\ProcessMining\test_with_graphics.py", line 178, in start_analyser
    display_single_column_table(nodes, 'Nodes', 'Nodes')
    ^^^^^^^^^^^^^^^^^^^^^^^^^^^
NameError: name 'display_single_column_table' is not defined

2024-08-13 00:29:29,949 ERROR: An error occurred while processing file : C:\projects\processMining\event logs\Insurance_claims_event_log.csv unsupported operand type(s) for +: 'int' and 'dict'
Traceback (most recent call last):
  File "c:\projects\ProcessMining\alpha_algo_app.py", line 582, in start_analyser
    directly_follows = compute_directly_follows(traces_dict,initial_events, final_events)
                       ^^^^^^^^^^^^^^^^^^^^^^^^^^^^^^^^^^^^^^^^^^^^^^^^^^^^^^^^^^^^^^^^^^
  File "c:\projects\ProcessMining\alpha_algo_app.py", line 133, in compute_directly_follows
    directly_follows[('start', trace[0])] = directly_follows.get(('start', trace[0]), 0) + qty
                                            ~~~~~~~~~~~~~~~~~~~~~~~~~~~~~~~~~~~~~~~~~~~~~^~~~~
TypeError: unsupported operand type(s) for +: 'int' and 'dict'

2024-08-13 00:29:35,822 ERROR: An error occurred while processing file: log2.csv unsupported operand type(s) for +: 'int' and 'dict'
Traceback (most recent call last):
  File "C:\projects\ProcessMining\test_with_graphics.py", line 393, in start_analyser
    directly_follows = alpha_algo_app.compute_directly_follows(traces_dict, initial_events, final_events)
                       ^^^^^^^^^^^^^^^^^^^^^^^^^^^^^^^^^^^^^^^^^^^^^^^^^^^^^^^^^^^^^^^^^^^^^^^^^^^^^^^^^^
  File "c:\projects\ProcessMining\alpha_algo_app.py", line 133, in compute_directly_follows
    directly_follows[('start', trace[0])] = directly_follows.get(('start', trace[0]), 0) + qty
                                            ~~~~~~~~~~~~~~~~~~~~~~~~~~~~~~~~~~~~~~~~~~~~~^~~~~
TypeError: unsupported operand type(s) for +: 'int' and 'dict'

2024-08-13 00:32:55,699 ERROR: An error occurred while processing file : C:\projects\processMining\event logs\Insurance_claims_event_log.csv 0
Traceback (most recent call last):
  File "c:\projects\ProcessMining\alpha_algo_app.py", line 582, in start_analyser
    directly_follows = compute_directly_follows(traces_dict,initial_events, final_events)
                       ^^^^^^^^^^^^^^^^^^^^^^^^^^^^^^^^^^^^^^^^^^^^^^^^^^^^^^^^^^^^^^^^^^
  File "c:\projects\ProcessMining\alpha_algo_app.py", line 133, in compute_directly_follows
    directly_follows[('start', trace[0])] = directly_follows.get(('start', trace[0]), 0) + qty[0]
                                                                                           ~~~^^^
KeyError: 0

2024-08-13 00:32:55,707 ERROR: An error occurred while processing file: log2.csv 0
Traceback (most recent call last):
  File "C:\projects\ProcessMining\test_with_graphics.py", line 393, in start_analyser
    directly_follows = alpha_algo_app.compute_directly_follows(traces_dict, initial_events, final_events)
                       ^^^^^^^^^^^^^^^^^^^^^^^^^^^^^^^^^^^^^^^^^^^^^^^^^^^^^^^^^^^^^^^^^^^^^^^^^^^^^^^^^^
  File "c:\projects\ProcessMining\alpha_algo_app.py", line 133, in compute_directly_follows
    directly_follows[('start', trace[0])] = directly_follows.get(('start', trace[0]), 0) + qty[0]
                                                                                           ~~~^^^
KeyError: 0

2024-08-13 00:34:46,197 ERROR: An error occurred while processing file : C:\projects\processMining\event logs\Insurance_claims_event_log.csv unsupported operand type(s) for +: 'int' and 'str'
Traceback (most recent call last):
  File "c:\projects\ProcessMining\alpha_algo_app.py", line 582, in start_analyser
    directly_follows = compute_directly_follows(traces_dict,initial_events, final_events)
                       ^^^^^^^^^^^^^^^^^^^^^^^^^^^^^^^^^^^^^^^^^^^^^^^^^^^^^^^^^^^^^^^^^^
  File "c:\projects\ProcessMining\alpha_algo_app.py", line 133, in compute_directly_follows
    directly_follows[('start', trace[0])] = directly_follows.get(('start', trace[0]), 0) + qty
                                            ~~~~~~~~~~~~~~~~~~~~~~~~~~~~~~~~~~~~~~~~~~~~~^~~~~
TypeError: unsupported operand type(s) for +: 'int' and 'str'

2024-08-13 00:34:46,255 ERROR: An error occurred while processing file: log2.csv unsupported operand type(s) for +: 'int' and 'str'
Traceback (most recent call last):
  File "C:\projects\ProcessMining\test_with_graphics.py", line 393, in start_analyser
    directly_follows = alpha_algo_app.compute_directly_follows(traces_dict, initial_events, final_events)
                       ^^^^^^^^^^^^^^^^^^^^^^^^^^^^^^^^^^^^^^^^^^^^^^^^^^^^^^^^^^^^^^^^^^^^^^^^^^^^^^^^^^
  File "c:\projects\ProcessMining\alpha_algo_app.py", line 133, in compute_directly_follows
    directly_follows[('start', trace[0])] = directly_follows.get(('start', trace[0]), 0) + qty
                                            ~~~~~~~~~~~~~~~~~~~~~~~~~~~~~~~~~~~~~~~~~~~~~^~~~~
TypeError: unsupported operand type(s) for +: 'int' and 'str'

2024-08-13 00:34:47,164 ERROR: An error occurred while processing file: log2.csv unsupported operand type(s) for +: 'int' and 'str'
Traceback (most recent call last):
  File "C:\projects\ProcessMining\test_with_graphics.py", line 393, in start_analyser
    directly_follows = alpha_algo_app.compute_directly_follows(traces_dict, initial_events, final_events)
                       ^^^^^^^^^^^^^^^^^^^^^^^^^^^^^^^^^^^^^^^^^^^^^^^^^^^^^^^^^^^^^^^^^^^^^^^^^^^^^^^^^^
  File "c:\projects\ProcessMining\alpha_algo_app.py", line 133, in compute_directly_follows
    directly_follows[('start', trace[0])] = directly_follows.get(('start', trace[0]), 0) + qty
                                            ~~~~~~~~~~~~~~~~~~~~~~~~~~~~~~~~~~~~~~~~~~~~~^~~~~
TypeError: unsupported operand type(s) for +: 'int' and 'str'

2024-08-13 00:39:47,540 ERROR: An error occurred while processing file: Insurance_claims_event_log.csv 3 columns passed, passed data had 2 columns
Traceback (most recent call last):
  File "C:\projects\ProcessMining\pm-training-alpha-miner\streamlit\Lib\site-packages\pandas\core\internals\construction.py", line 939, in _finalize_columns_and_data
    columns = _validate_or_indexify_columns(contents, columns)
              ^^^^^^^^^^^^^^^^^^^^^^^^^^^^^^^^^^^^^^^^^^^^^^^^
  File "C:\projects\ProcessMining\pm-training-alpha-miner\streamlit\Lib\site-packages\pandas\core\internals\construction.py", line 986, in _validate_or_indexify_columns
    raise AssertionError(
AssertionError: 3 columns passed, passed data had 2 columns

The above exception was the direct cause of the following exception:

Traceback (most recent call last):
  File "C:\projects\ProcessMining\test_with_graphics.py", line 410, in start_analyser
    display_traces_table(traces_dict)
  File "C:\projects\ProcessMining\test_with_graphics.py", line 109, in display_traces_table
    traces_df = pd.DataFrame(list(traces_dict.items()), columns=['Sequence', 'Quantity' , 'Frequency'])
                ^^^^^^^^^^^^^^^^^^^^^^^^^^^^^^^^^^^^^^^^^^^^^^^^^^^^^^^^^^^^^^^^^^^^^^^^^^^^^^^^^^^^^^^
  File "C:\projects\ProcessMining\pm-training-alpha-miner\streamlit\Lib\site-packages\pandas\core\frame.py", line 851, in __init__
    arrays, columns, index = nested_data_to_arrays(
                             ^^^^^^^^^^^^^^^^^^^^^^
  File "C:\projects\ProcessMining\pm-training-alpha-miner\streamlit\Lib\site-packages\pandas\core\internals\construction.py", line 520, in nested_data_to_arrays
    arrays, columns = to_arrays(data, columns, dtype=dtype)
                      ^^^^^^^^^^^^^^^^^^^^^^^^^^^^^^^^^^^^^
  File "C:\projects\ProcessMining\pm-training-alpha-miner\streamlit\Lib\site-packages\pandas\core\internals\construction.py", line 845, in to_arrays
    content, columns = _finalize_columns_and_data(arr, columns, dtype)
                       ^^^^^^^^^^^^^^^^^^^^^^^^^^^^^^^^^^^^^^^^^^^^^^^
  File "C:\projects\ProcessMining\pm-training-alpha-miner\streamlit\Lib\site-packages\pandas\core\internals\construction.py", line 942, in _finalize_columns_and_data
    raise ValueError(err) from err
ValueError: 3 columns passed, passed data had 2 columns

2024-08-14 12:23:50,568 ERROR: An error occurred: [Errno 2] No such file or directory: 'C:\\projects\\processMining\\event logs\\analyser_script_log.log'
2024-08-14 12:23:50,588 ERROR: Traceback (most recent call last):
  File "c:\projects\ProcessMining\alpha_algo_app.py", line 333, in start_analyser
    trace_dict = read_log_file(log_file_name)
                 ^^^^^^^^^^^^^^^^^^^^^^^^^^^^
  File "c:\projects\ProcessMining\alpha_algo_app.py", line 41, in read_log_file
    df_log = pd.read_csv(analysed_log, usecols=['case_id', 'activity_name', 'timestamp'])
             ^^^^^^^^^^^^^^^^^^^^^^^^^^^^^^^^^^^^^^^^^^^^^^^^^^^^^^^^^^^^^^^^^^^^^^^^^^^^
  File "C:\Users\it_su\AppData\Roaming\Python\Python312\site-packages\pandas\io\parsers\readers.py", line 1026, in read_csv
    return _read(filepath_or_buffer, kwds)
           ^^^^^^^^^^^^^^^^^^^^^^^^^^^^^^^
  File "C:\Users\it_su\AppData\Roaming\Python\Python312\site-packages\pandas\io\parsers\readers.py", line 620, in _read
    parser = TextFileReader(filepath_or_buffer, **kwds)
             ^^^^^^^^^^^^^^^^^^^^^^^^^^^^^^^^^^^^^^^^^^
  File "C:\Users\it_su\AppData\Roaming\Python\Python312\site-packages\pandas\io\parsers\readers.py", line 1620, in __init__
    self._engine = self._make_engine(f, self.engine)
                   ^^^^^^^^^^^^^^^^^^^^^^^^^^^^^^^^^
  File "C:\Users\it_su\AppData\Roaming\Python\Python312\site-packages\pandas\io\parsers\readers.py", line 1880, in _make_engine
    self.handles = get_handle(
                   ^^^^^^^^^^^
  File "C:\Users\it_su\AppData\Roaming\Python\Python312\site-packages\pandas\io\common.py", line 873, in get_handle
    handle = open(
             ^^^^^
FileNotFoundError: [Errno 2] No such file or directory: 'C:\\projects\\processMining\\event logs\\analyser_script_log.log'

2024-08-14 12:26:05,340 INFO: Footprint Matrix: {('a', 'a'): ' # ', ('a', 'c'): '-->', ('a', 'b'): '-->', ('a', 'e'): ' # ', ('a', 'd'): ' # ', ('c', 'a'): '<--', ('c', 'c'): ' # ', ('c', 'b'): '| |', ('c', 'e'): '-->', ('c', 'd'): '| |', ('b', 'a'): '<--', ('b', 'c'): '| |', ('b', 'b'): ' # ', ('b', 'e'): '-->', ('b', 'd'): '| |', ('e', 'a'): ' # ', ('e', 'c'): '<--', ('e', 'b'): '<--', ('e', 'e'): ' # ', ('e', 'd'): ' # ', ('d', 'a'): ' # ', ('d', 'c'): '| |', ('d', 'b'): '| |', ('d', 'e'): ' # ', ('d', 'd'): ' # '}
2024-08-14 12:26:05,341 INFO: Independent Sets: [{'a'}, {'c'}, {'b'}, {'e'}, {'d'}, {'a', 'e'}, {'a', 'd'}, {'e', 'd'}, {'a', 'e', 'd'}]
2024-08-14 12:26:05,341 INFO: Transitions: {(('a',), ('c',)): '-->', (('a',), ('b',)): '-->', (('c',), ('b',)): '| |', (('c',), ('e',)): '-->', (('c',), ('d',)): '| |', (('b',), ('e',)): '-->', (('b',), ('d',)): '| |'}
2024-08-14 12:26:05,341 INFO: Maximal Sets: [{'c'}, {'b'}]
2024-08-14 12:26:05,341 INFO: Classified Transitions: {(('a',), ('c',)): 'direct', (('a',), ('b',)): 'direct', (('c',), ('b',)): 'mutual', (('c',), ('e',)): 'direct', (('c',), ('d',)): 'mutual', (('b',), ('e',)): 'direct', (('b',), ('d',)): 'mutual'}
2024-08-14 12:26:50,099 INFO: Footprint Matrix: {('e', 'e'): ' # ', ('e', 'g'): '-->', ('e', 'b'): ' # ', ('e', 'f'): ' # ', ('e', 'd'): ' # ', ('e', 'c'): '| |', ('e', 'a'): '<--', ('g', 'e'): '<--', ('g', 'g'): ' # ', ('g', 'b'): ' # ', ('g', 'f'): '<--', ('g', 'd'): '<--', ('g', 'c'): '<--', ('g', 'a'): ' # ', ('b', 'e'): ' # ', ('b', 'g'): ' # ', ('b', 'b'): ' # ', ('b', 'f'): '-->', ('b', 'd'): '-->', ('b', 'c'): ' # ', ('b', 'a'): ' # ', ('f', 'e'): ' # ', ('f', 'g'): '-->', ('f', 'b'): '<--', ('f', 'f'): ' # ', ('f', 'd'): '| |', ('f', 'c'): ' # ', ('f', 'a'): ' # ', ('d', 'e'): ' # ', ('d', 'g'): '-->', ('d', 'b'): '<--', ('d', 'f'): '| |', ('d', 'd'): ' # ', ('d', 'c'): ' # ', ('d', 'a'): ' # ', ('c', 'e'): '| |', ('c', 'g'): '-->', ('c', 'b'): ' # ', ('c', 'f'): ' # ', ('c', 'd'): ' # ', ('c', 'c'): ' # ', ('c', 'a'): '<--', ('a', 'e'): '-->', ('a', 'g'): ' # ', ('a', 'b'): ' # ', ('a', 'f'): ' # ', ('a', 'd'): ' # ', ('a', 'c'): '-->', ('a', 'a'): ' # '}
2024-08-14 12:26:50,099 INFO: Independent Sets: [{'e'}, {'g'}, {'b'}, {'f'}, {'d'}, {'c'}, {'a'}, {'e', 'b'}, {'e', 'f'}, {'e', 'd'}, {'g', 'b'}, {'a', 'g'}, {'c', 'b'}, {'a', 'b'}, {'f', 'c'}, {'f', 'a'}, {'d', 'c'}, {'a', 'd'}, {'a', 'g', 'b'}]
2024-08-14 12:26:50,099 INFO: Transitions: {(('e',), ('g',)): '-->', (('e',), ('c',)): '| |', (('a',), ('e',)): '-->', (('f',), ('g',)): '-->', (('d',), ('g',)): '-->', (('c',), ('g',)): '-->', (('e', 'f'), ('g',)): '-->', (('e', 'd'), ('g',)): '-->', (('f', 'c'), ('g',)): '-->', (('d', 'c'), ('g',)): '-->', (('b',), ('f',)): '-->', (('b',), ('d',)): '-->', (('f',), ('d',)): '| |', (('a',), ('c',)): '-->'}
2024-08-14 12:26:50,099 INFO: Maximal Sets: [{'e', 'f'}, {'e', 'd'}, {'f', 'c'}, {'d', 'c'}]
2024-08-14 12:26:50,099 INFO: Classified Transitions: {(('e',), ('g',)): 'direct', (('e',), ('c',)): 'mutual', (('a',), ('e',)): 'direct', (('f',), ('g',)): 'direct', (('d',), ('g',)): 'direct', (('c',), ('g',)): 'direct', (('e', 'f'), ('g',)): 'direct', (('e', 'd'), ('g',)): 'direct', (('f', 'c'), ('g',)): 'direct', (('d', 'c'), ('g',)): 'direct', (('b',), ('f',)): 'direct', (('b',), ('d',)): 'direct', (('f',), ('d',)): 'mutual', (('a',), ('c',)): 'direct'}
2024-08-14 13:42:19,039 ERROR: Error during analysis: filter_maximal_sets() missing 1 required positional argument: 'transitions'
2024-08-14 14:29:52,466 ERROR: Error during analysis: classify_transitions() missing 1 required positional argument: 'independent_sets'
2024-08-14 14:29:54,851 ERROR: Error during analysis: classify_transitions() missing 1 required positional argument: 'independent_sets'
2024-08-14 14:31:33,941 ERROR: Error during analysis: 'list' object has no attribute 'items'
2024-08-14 14:31:54,216 ERROR: Error during analysis: 'list' object has no attribute 'items'
2024-08-14 14:32:15,683 ERROR: Error during analysis: 3 columns passed, passed data had 2 columns
2024-08-14 14:34:58,947 ERROR: Error during analysis: Index(...) must be called with a collection of some kind, 'Nodes' was passed
2024-08-14 15:16:51,075 ERROR: An error occurred while processing file: edited_Insurance_claims_event_log.csv filter_maximal_sets() missing 1 required positional argument: 'transitions'
Traceback (most recent call last):
  File "C:\projects\ProcessMining\test_with_graphics.py", line 184, in start_analyser
    filtered_transitions = alpha_algo_app.filter_maximal_sets(transitions)
                           ^^^^^^^^^^^^^^^^^^^^^^^^^^^^^^^^^^^^^^^^^^^^^^^
TypeError: filter_maximal_sets() missing 1 required positional argument: 'transitions'

2024-08-14 15:22:51,127 ERROR: An error occurred while processing file: edited_Insurance_claims_event_log.csv 'list' object has no attribute 'items'
Traceback (most recent call last):
  File "C:\projects\ProcessMining\test_with_graphics.py", line 197, in start_analyser
    display_two_column_table(list(filtered_transitions.items()), ('Filtered Sequence', 'Transition'), 'Filtered Transitions')
                                  ^^^^^^^^^^^^^^^^^^^^^^^^^^
AttributeError: 'list' object has no attribute 'items'

2024-08-14 15:23:44,791 ERROR: An error occurred while processing file: edited_Insurance_claims_event_log.csv 'list' object has no attribute 'items'
Traceback (most recent call last):
  File "C:\projects\ProcessMining\test_with_graphics.py", line 197, in start_analyser
    display_two_column_table(list(filtered_transitions.items()), ('Filtered Sequence', 'Transition'), 'Filtered Transitions')
                                  ^^^^^^^^^^^^^^^^^^^^^^^^^^
AttributeError: 'list' object has no attribute 'items'

2024-08-14 15:24:48,215 ERROR: An error occurred while processing file: edited_Insurance_claims_event_log.csv 'list' object has no attribute 'items'
Traceback (most recent call last):
  File "C:\projects\ProcessMining\test_with_graphics.py", line 199, in start_analyser
    diagram_path = create_process_diagram(initial_events, final_events, nodes, filtered_transitions)
                   ^^^^^^^^^^^^^^^^^^^^^^^^^^^^^^^^^^^^^^^^^^^^^^^^^^^^^^^^^^^^^^^^^^^^^^^^^^^^^^^^^
  File "C:\projects\ProcessMining\test_with_graphics.py", line 145, in create_process_diagram
    for (source, target), relationship in filtered_transitions.items():
                                          ^^^^^^^^^^^^^^^^^^^^^^^^^^
AttributeError: 'list' object has no attribute 'items'

2024-08-14 15:27:44,030 ERROR: An error occurred while processing file: edited_Insurance_claims_event_log.csv 'list' object has no attribute 'items'
Traceback (most recent call last):
  File "C:\projects\ProcessMining\test_with_graphics.py", line 226, in start_analyser
    diagram_path = create_process_diagram(initial_events, final_events, nodes, filtered_transitions)
                   ^^^^^^^^^^^^^^^^^^^^^^^^^^^^^^^^^^^^^^^^^^^^^^^^^^^^^^^^^^^^^^^^^^^^^^^^^^^^^^^^^
  File "C:\projects\ProcessMining\test_with_graphics.py", line 161, in create_process_diagram
    for (source, target), relationship in filtered_transitions.items():
                                          ^^^^^^^^^^^^^^^^^^^^^^^^^^
AttributeError: 'list' object has no attribute 'items'

2024-08-14 15:28:35,577 ERROR: An error occurred while processing file: Insurance_claims_event_log.csv not enough values to unpack (expected 2, got 1)
Traceback (most recent call last):
  File "C:\projects\ProcessMining\test_with_graphics.py", line 226, in start_analyser
    diagram_path = create_process_diagram(initial_events, final_events, nodes, filtered_transitions)
                   ^^^^^^^^^^^^^^^^^^^^^^^^^^^^^^^^^^^^^^^^^^^^^^^^^^^^^^^^^^^^^^^^^^^^^^^^^^^^^^^^^
  File "C:\projects\ProcessMining\test_with_graphics.py", line 161, in create_process_diagram
    for (source, target), relationship in filtered_transitions:
        ^^^^^^^^^^^^^^^^^^^^^^^^^^^^^^
ValueError: not enough values to unpack (expected 2, got 1)

2024-08-14 15:28:43,493 ERROR: An error occurred while processing file: log1.csv 2 columns passed, passed data had 1 columns
Traceback (most recent call last):
  File "C:\projects\ProcessMining\.venv\Lib\site-packages\pandas\core\internals\construction.py", line 939, in _finalize_columns_and_data
    columns = _validate_or_indexify_columns(contents, columns)
              ^^^^^^^^^^^^^^^^^^^^^^^^^^^^^^^^^^^^^^^^^^^^^^^^
  File "C:\projects\ProcessMining\.venv\Lib\site-packages\pandas\core\internals\construction.py", line 986, in _validate_or_indexify_columns
    raise AssertionError(
AssertionError: 2 columns passed, passed data had 1 columns

The above exception was the direct cause of the following exception:

Traceback (most recent call last):
  File "C:\projects\ProcessMining\test_with_graphics.py", line 224, in start_analyser
    display_two_column_table(filtered_transitions, ('Filtered Sequence', 'Transition'), 'Filtered Transitions')
  File "C:\projects\ProcessMining\test_with_graphics.py", line 117, in display_two_column_table
    df = pd.DataFrame(data, columns=column_names)
         ^^^^^^^^^^^^^^^^^^^^^^^^^^^^^^^^^^^^^^^^
  File "C:\projects\ProcessMining\.venv\Lib\site-packages\pandas\core\frame.py", line 851, in __init__
    arrays, columns, index = nested_data_to_arrays(
                             ^^^^^^^^^^^^^^^^^^^^^^
  File "C:\projects\ProcessMining\.venv\Lib\site-packages\pandas\core\internals\construction.py", line 520, in nested_data_to_arrays
    arrays, columns = to_arrays(data, columns, dtype=dtype)
                      ^^^^^^^^^^^^^^^^^^^^^^^^^^^^^^^^^^^^^
  File "C:\projects\ProcessMining\.venv\Lib\site-packages\pandas\core\internals\construction.py", line 845, in to_arrays
    content, columns = _finalize_columns_and_data(arr, columns, dtype)
                       ^^^^^^^^^^^^^^^^^^^^^^^^^^^^^^^^^^^^^^^^^^^^^^^
  File "C:\projects\ProcessMining\.venv\Lib\site-packages\pandas\core\internals\construction.py", line 942, in _finalize_columns_and_data
    raise ValueError(err) from err
ValueError: 2 columns passed, passed data had 1 columns

2024-08-14 15:29:33,382 ERROR: An error occurred while processing file: log2.csv not enough values to unpack (expected 2, got 1)
Traceback (most recent call last):
  File "C:\projects\ProcessMining\test_with_graphics.py", line 226, in start_analyser
    diagram_path = create_process_diagram(initial_events, final_events, nodes, filtered_transitions)
                   ^^^^^^^^^^^^^^^^^^^^^^^^^^^^^^^^^^^^^^^^^^^^^^^^^^^^^^^^^^^^^^^^^^^^^^^^^^^^^^^^^
  File "C:\projects\ProcessMining\test_with_graphics.py", line 161, in create_process_diagram
    for (source, target), relationship in filtered_transitions:
        ^^^^^^^^^^^^^^^^
ValueError: not enough values to unpack (expected 2, got 1)

2024-08-14 15:29:57,125 INFO: Footprint Matrix: {('b', 'b'): ' # ', ('b', 'g'): ' # ', ('b', 'a'): ' # ', ('b', 'd'): '-->', ('b', 'e'): ' # ', ('b', 'c'): ' # ', ('b', 'f'): '-->', ('g', 'b'): ' # ', ('g', 'g'): ' # ', ('g', 'a'): ' # ', ('g', 'd'): '<--', ('g', 'e'): '<--', ('g', 'c'): '<--', ('g', 'f'): '<--', ('a', 'b'): ' # ', ('a', 'g'): ' # ', ('a', 'a'): ' # ', ('a', 'd'): ' # ', ('a', 'e'): '-->', ('a', 'c'): '-->', ('a', 'f'): ' # ', ('d', 'b'): '<--', ('d', 'g'): '-->', ('d', 'a'): ' # ', ('d', 'd'): ' # ', ('d', 'e'): ' # ', ('d', 'c'): ' # ', ('d', 'f'): '| |', ('e', 'b'): ' # ', ('e', 'g'): '-->', ('e', 'a'): '<--', ('e', 'd'): ' # ', ('e', 'e'): ' # ', ('e', 'c'): '| |', ('e', 'f'): ' # ', ('c', 'b'): ' # ', ('c', 'g'): '-->', ('c', 'a'): '<--', ('c', 'd'): ' # ', ('c', 'e'): '| |', ('c', 'c'): ' # ', ('c', 'f'): ' # ', ('f', 'b'): '<--', ('f', 'g'): '-->', ('f', 'a'): ' # ', ('f', 'd'): '| |', ('f', 'e'): ' # ', ('f', 'c'): ' # ', ('f', 'f'): ' # '}
2024-08-14 15:29:57,125 INFO: Independent Sets: [{'b'}, {'g'}, {'e'}, {'d'}, {'a'}, {'c'}, {'f'}, {'b', 'g'}, {'e', 'b'}, {'b', 'a'}, {'b', 'c'}, {'g', 'a'}, {'e', 'd'}, {'e', 'f'}, {'a', 'd'}, {'d', 'c'}, {'a', 'f'}, {'c', 'f'}, {'b', 'g', 'a'}]
2024-08-14 15:29:57,125 INFO: Transitions: {(('b',), ('d',)): '-->', (('b',), ('f',)): '-->', (('e',), ('g',)): '-->', (('d',), ('g',)): '-->', (('c',), ('g',)): '-->', (('f',), ('g',)): '-->', (('e', 'd'), ('g',)): '-->', (('e', 'f'), ('g',)): '-->', (('d', 'c'), ('g',)): '-->', (('c', 'f'), ('g',)): '-->', (('a',), ('e',)): '-->', (('e',), ('c',)): '| |', (('d',), ('f',)): '| |', (('a',), ('c',)): '-->'}
2024-08-14 15:29:57,125 INFO: Maximal Sets: [{'e', 'd'}, {'e', 'f'}, {'d', 'c'}, {'c', 'f'}]
2024-08-14 15:29:57,126 INFO: Classified Transitions: {(('b',), ('d',)): 'direct', (('b',), ('f',)): 'direct', (('e',), ('g',)): 'direct', (('d',), ('g',)): 'direct', (('c',), ('g',)): 'direct', (('f',), ('g',)): 'direct', (('e', 'd'), ('g',)): 'direct', (('e', 'f'), ('g',)): 'direct', (('d', 'c'), ('g',)): 'direct', (('c', 'f'), ('g',)): 'direct', (('a',), ('e',)): 'direct', (('e',), ('c',)): 'mutual', (('d',), ('f',)): 'mutual', (('a',), ('c',)): 'direct'}
2024-08-14 15:33:55,518 INFO: Footprint Matrix: {('d', 'd'): ' # ', ('d', 'g'): '-->', ('d', 'c'): ' # ', ('d', 'f'): '| |', ('d', 'e'): ' # ', ('d', 'b'): '<--', ('d', 'a'): ' # ', ('g', 'd'): '<--', ('g', 'g'): ' # ', ('g', 'c'): '<--', ('g', 'f'): '<--', ('g', 'e'): '<--', ('g', 'b'): ' # ', ('g', 'a'): ' # ', ('c', 'd'): ' # ', ('c', 'g'): '-->', ('c', 'c'): ' # ', ('c', 'f'): ' # ', ('c', 'e'): '| |', ('c', 'b'): ' # ', ('c', 'a'): '<--', ('f', 'd'): '| |', ('f', 'g'): '-->', ('f', 'c'): ' # ', ('f', 'f'): ' # ', ('f', 'e'): ' # ', ('f', 'b'): '<--', ('f', 'a'): ' # ', ('e', 'd'): ' # ', ('e', 'g'): '-->', ('e', 'c'): '| |', ('e', 'f'): ' # ', ('e', 'e'): ' # ', ('e', 'b'): ' # ', ('e', 'a'): '<--', ('b', 'd'): '-->', ('b', 'g'): ' # ', ('b', 'c'): ' # ', ('b', 'f'): '-->', ('b', 'e'): ' # ', ('b', 'b'): ' # ', ('b', 'a'): ' # ', ('a', 'd'): ' # ', ('a', 'g'): ' # ', ('a', 'c'): '-->', ('a', 'f'): ' # ', ('a', 'e'): '-->', ('a', 'b'): ' # ', ('a', 'a'): ' # '}
2024-08-14 15:33:55,518 INFO: Independent Sets: [{'d'}, {'g'}, {'c'}, {'f'}, {'e'}, {'b'}, {'a'}, {'d', 'c'}, {'e', 'd'}, {'d', 'a'}, {'g', 'b'}, {'g', 'a'}, {'f', 'c'}, {'c', 'b'}, {'f', 'e'}, {'f', 'a'}, {'e', 'b'}, {'b', 'a'}, {'a', 'g', 'b'}]
2024-08-14 15:33:55,518 INFO: Transitions: {(('d',), ('g',)): '-->', (('d',), ('f',)): '| |', (('b',), ('d',)): '-->', (('c',), ('g',)): '-->', (('f',), ('g',)): '-->', (('e',), ('g',)): '-->', (('d', 'c'), ('g',)): '-->', (('e', 'd'), ('g',)): '-->', (('f', 'c'), ('g',)): '-->', (('f', 'e'), ('g',)): '-->', (('c',), ('e',)): '| |', (('a',), ('c',)): '-->', (('b',), ('f',)): '-->', (('a',), ('e',)): '-->'}
2024-08-14 15:33:55,518 INFO: Maximal Sets: {(('d',), ('f',)): '| |', (('b',), ('d',)): '-->', (('d', 'c'), ('g',)): '-->', (('e', 'd'), ('g',)): '-->', (('f', 'c'), ('g',)): '-->', (('f', 'e'), ('g',)): '-->', (('c',), ('e',)): '| |', (('a',), ('c',)): '-->', (('b',), ('f',)): '-->', (('a',), ('e',)): '-->'}
2024-08-14 15:34:48,549 ERROR: An error occurred while processing file: log2.csv not enough values to unpack (expected 2, got 1)
Traceback (most recent call last):
  File "C:\projects\ProcessMining\test_with_graphics.py", line 226, in start_analyser
    diagram_path = create_process_diagram(initial_events, final_events, nodes, filtered_transitions)
                   ^^^^^^^^^^^^^^^^^^^^^^^^^^^^^^^^^^^^^^^^^^^^^^^^^^^^^^^^^^^^^^^^^^^^^^^^^^^^^^^^^
  File "C:\projects\ProcessMining\test_with_graphics.py", line 161, in create_process_diagram
    for (source, target), relationship in filtered_transitions:
        ^^^^^^^^^^^^^^^^
ValueError: not enough values to unpack (expected 2, got 1)

2024-08-14 15:34:50,395 ERROR: An error occurred while processing file: log2.csv not enough values to unpack (expected 2, got 1)
Traceback (most recent call last):
  File "C:\projects\ProcessMining\test_with_graphics.py", line 226, in start_analyser
    diagram_path = create_process_diagram(initial_events, final_events, nodes, filtered_transitions)
                   ^^^^^^^^^^^^^^^^^^^^^^^^^^^^^^^^^^^^^^^^^^^^^^^^^^^^^^^^^^^^^^^^^^^^^^^^^^^^^^^^^
  File "C:\projects\ProcessMining\test_with_graphics.py", line 161, in create_process_diagram
    for (source, target), relationship in filtered_transitions:
        ^^^^^^^^^^^^^^^^
ValueError: not enough values to unpack (expected 2, got 1)

